<?xml version="1.0" encoding="UTF-8"?>
<!-- Generated by org.testng.reporters.JUnitReportReporter -->
<testsuite hostname="P11-AS-CHSSXC2" name="com.altisource.MPT_test.Sync_ServiceExecutableTest" tests="1" failures="0" timestamp="27 Nov 2017 15:49:13 GMT" time="0.016" errors="1">
  <testcase name="runSync_ServiceExecutable" time="0.016" classname="com.altisource.MPT_test.Sync_ServiceExecutableTest">
    <error type="java.lang.AssertionError" message="Something went wrong, while execution of Sync service expected [false] but found [true]">
      <![CDATA[java.lang.AssertionError: Something went wrong, while execution of Sync service expected [false] but found [true]
	at com.altisource.framework.SoftAsserts.fail(SoftAsserts.java:82)
	at com.altisource.framework.SoftAsserts.failNotEquals(SoftAsserts.java:482)
	at com.altisource.framework.SoftAsserts.assertEquals(SoftAsserts.java:111)
	at com.altisource.framework.SoftAsserts.assertEquals(SoftAsserts.java:274)
	at com.altisource.framework.ProjectUtils.executeSyncService(ProjectUtils.java:128)
	at com.altisource.MPT_test.Sync_ServiceExecutableTest.runSync_ServiceExecutable(Sync_ServiceExecutableTest.java:12)
	at sun.reflect.NativeMethodAccessorImpl.invoke0(Native Method)
	at sun.reflect.NativeMethodAccessorImpl.invoke(NativeMethodAccessorImpl.java:62)
	at sun.reflect.DelegatingMethodAccessorImpl.invoke(DelegatingMethodAccessorImpl.java:43)
	at java.lang.reflect.Method.invoke(Method.java:498)
	at org.testng.internal.MethodInvocationHelper.invokeMethod(MethodInvocationHelper.java:80)
	at org.testng.internal.Invoker.invokeMethod(Invoker.java:715)
	at org.testng.internal.Invoker.invokeTestMethod(Invoker.java:907)
	at org.testng.internal.Invoker.invokeTestMethods(Invoker.java:1237)
	at org.testng.internal.TestMethodWorker.invokeTestMethods(TestMethodWorker.java:127)
	at org.testng.internal.TestMethodWorker.run(TestMethodWorker.java:111)
	at org.testng.TestRunner.privateRun(TestRunner.java:767)
	at org.testng.TestRunner.run(TestRunner.java:617)
	at org.testng.SuiteRunner.runTest(SuiteRunner.java:334)
	at org.testng.SuiteRunner.runSequentially(SuiteRunner.java:329)
	at org.testng.SuiteRunner.privateRun(SuiteRunner.java:291)
	at org.testng.SuiteRunner.run(SuiteRunner.java:240)
	at org.testng.SuiteRunnerWorker.runSuite(SuiteRunnerWorker.java:51)
	at org.testng.SuiteRunnerWorker.run(SuiteRunnerWorker.java:85)
	at org.testng.TestNG.runSuitesSequentially(TestNG.java:1197)
	at org.testng.TestNG.runSuitesLocally(TestNG.java:1122)
	at org.testng.TestNG.run(TestNG.java:1030)
	at org.testng.remote.AbstractRemoteTestNG.run(AbstractRemoteTestNG.java:114)
	at org.testng.remote.RemoteTestNG.initAndRun(RemoteTestNG.java:251)
	at org.testng.remote.RemoteTestNG.main(RemoteTestNG.java:77)
]]>
    </error>
  </testcase> <!-- runSync_ServiceExecutable -->
</testsuite> <!-- com.altisource.MPT_test.Sync_ServiceExecutableTest -->
